Workbook
Name A1_billable_hours: '[1]1.0 Pricing & Role Selection'!$J$31
Name A1_nonbillable_hours: '[1]1.0 Pricing & Role Selection'!$K$31
Name A10_billable_hours: '[1]1.0 Pricing & Role Selection'!$J$40
Name A10_nonbillable_hours: '[1]1.0 Pricing & Role Selection'!$K$40
Name A11_billable_hours: '[1]1.0 Pricing & Role Selection'!$J$41
Name A11_nonbillable_hours: '[1]1.0 Pricing & Role Selection'!$K$41
Name A12_billable_hours: '[1]1.0 Pricing & Role Selection'!$J$42
Name A12_nonbillable_hours: '[1]1.0 Pricing & Role Selection'!$K$42
Name A13_billable_hours: '[1]1.0 Pricing & Role Selection'!$J$43
Name A13_nonbillable_hours: '[1]1.0 Pricing & Role Selection'!$K$43
Name A14_billable_hours: '[1]1.0 Pricing & Role Selection'!$J$44
Name A14_nonbillable_hours: '[1]1.0 Pricing & Role Selection'!$K$44
Name A15_billable_hours: '[1]1.0 Pricing & Role Selection'!$J$45
Name A15_nonbillable_hours: '[1]1.0 Pricing & Role Selection'!$K$45
Name A2_billable_hours: '[1]1.0 Pricing & Role Selection'!$J$32
Name A2_nonbillable_hours: '[1]1.0 Pricing & Role Selection'!$K$32
Name A3_billable_hours: '[1]1.0 Pricing & Role Selection'!$J$33
Name A3_nonbillable_hours: '[1]1.0 Pricing & Role Selection'!$K$33
Name A4_billable_hours: '[1]1.0 Pricing & Role Selection'!$J$34
Name A4_nonbillable_hours: '[1]1.0 Pricing & Role Selection'!$K$34
Name A5_billable_hours: '[1]1.0 Pricing & Role Selection'!$J$35
Name A5_nonbillable_hours: '[1]1.0 Pricing & Role Selection'!$K$35
Name A6_billable_hours: '[1]1.0 Pricing & Role Selection'!$J$36
Name A6_nonbillable_hours: '[1]1.0 Pricing & Role Selection'!$K$36
Name A7_billable_hours: '[1]1.0 Pricing & Role Selection'!$J$37
Name A7_nonbillable_hours: '[1]1.0 Pricing & Role Selection'!$K$37
Name A8_billable_hours: '[1]1.0 Pricing & Role Selection'!$J$38
Name A8_nonbillable_hours: '[1]1.0 Pricing & Role Selection'!$K$38
Name A9_billable_hours: '[1]1.0 Pricing & Role Selection'!$J$39
Name A9_nonbillable_hours: '[1]1.0 Pricing & Role Selection'!$K$39
Name Agile_Tax: '[1]Opportunity Details'!$F$16
Name Agile_Tax: 'Opportunity Details'!$F$16
Name Applications_In_Scope: '[1]2.0 Scoping'!$C$2:$D$19
Name B1_billable_hours: '[1]1.0 Pricing & Role Selection'!$J$47
Name B1_nonbillable_hours: '[1]1.0 Pricing & Role Selection'!$K$47
Name B10_billable_hours: '[1]1.0 Pricing & Role Selection'!$J$56
Name B10_nonbillable_hours: '[1]1.0 Pricing & Role Selection'!$K$56
Name B11_billable_hours: '[1]1.0 Pricing & Role Selection'!$J$57
Name B11_nonbillable_hours: '[1]1.0 Pricing & Role Selection'!$K$57
Name B12_billable_hours: '[1]1.0 Pricing & Role Selection'!$J$58
Name B12_nonbillable_hours: '[1]1.0 Pricing & Role Selection'!$K$58
Name B13_billable_hours: '[1]1.0 Pricing & Role Selection'!$J$59
Name B13_nonbillable_hours: '[1]1.0 Pricing & Role Selection'!$K$59
Name B14_billable_hours: '[1]1.0 Pricing & Role Selection'!$J$60
Name B14_nonbillable_hours: '[1]1.0 Pricing & Role Selection'!$K$60
Name B15_billable_hours: '[1]1.0 Pricing & Role Selection'!$J$61
Name B15_nonbillable_hours: '[1]1.0 Pricing & Role Selection'!$K$61
Name B2_billable_hours: '[1]1.0 Pricing & Role Selection'!$J$48
Name B2_nonbillable_hours: '[1]1.0 Pricing & Role Selection'!$K$48
Name B3_billable_hours: '[1]1.0 Pricing & Role Selection'!$J$49
Name B3_nonbillable_hours: '[1]1.0 Pricing & Role Selection'!$K$49
Name B4_billable_hours: '[1]1.0 Pricing & Role Selection'!$J$50
Name B4_nonbillable_hours: '[1]1.0 Pricing & Role Selection'!$K$50
Name B5_billable_hours: '[1]1.0 Pricing & Role Selection'!$J$51
Name B5_nonbillable_hours: '[1]1.0 Pricing & Role Selection'!$K$51
Name B6_billable_hours: '[1]1.0 Pricing & Role Selection'!$J$52
Name B6_nonbillable_hours: '[1]1.0 Pricing & Role Selection'!$K$52
Name B7_billable_hours: '[1]1.0 Pricing & Role Selection'!$J$53
Name B7_nonbillable_hours: '[1]1.0 Pricing & Role Selection'!$K$53
Name B8_billable_hours: '[1]1.0 Pricing & Role Selection'!$J$54

Sheet Estimate - Master (2)
B2: ='Opportunity Details'!A3 -> Salesforce Opportunity Number | C2: =IF(ISBLANK('Opportunity Details'!C3), "Populate Sales Force ID on Opportunity Details Sheet", 'Opportunity Details'!C3) -> Populate Sales Force ID on Opportunity Details Sheet
B3: ='Opportunity Details'!A4 -> Opportunity Name | C3: =IF(ISBLANK('Opportunity Details'!C4),"Populate Engagement Title on Opportunity Details Sheet",'Opportunity Details'!C4) -> Acme Opportunity
B4: ='Opportunity Details'!A7 -> Account Name | C4: =IF(ISBLANK('Opportunity Details'!C7),"Populate Client on Opportunity Details Sheet",'Opportunity Details'!C7) -> Boeing ITSM Now Assist AI POC
B5: Use Case: | C5: Replace ITSM System
B6: Product Line | C6: IT Workflows
O7: IT Workflows | AB7: Customer and Employee Workflows | AP7: IRM / SecOps
O8: US | AB8: US | AP8: US
O9: =#REF! -> #REF! | P9: =#REF! -> #REF! | Q9: =#REF! -> #REF! | R9: =#REF! -> #REF! | S9: =#REF! -> #REF! | T9: =#REF! -> #REF! | U9: =#REF! -> #REF! | V9: =#REF! -> #REF! | ... Y9: =#REF! -> #REF! | AB9: =#REF! -> #REF! | AC9: =#REF! -> #REF! | AD9: =#REF! -> #REF! | AE9: =#REF! -> #REF! | AF9: =#REF! -> #REF! | AG9: =#REF! -> #REF! | AH9: =#REF! -> #REF! | AI9: =#REF! -> #REF! | ... AM9: =#REF! -> #REF! | AP9: =#REF! -> #REF! | AQ9: =#REF! -> #REF! | AR9: =#REF! -> #REF! | AS9: =#REF! -> #REF! | AT9: =#REF! -> #REF! | AU9: =#REF! -> #REF! | AV9: =#REF! -> #REF! | AW9: =#REF! -> #REF! | ... BA9: =#REF! -> #REF!
B10: STAGE | C10: Phase | D10: Task | E10: Description | F10: Assumption | G10: Project Role | H10: Billable/ Non-Billable | I10: Hours | J10: Rate / HR | K10: Estimated Cost | L10: Additional PM Oversight | M10: Additional BA Oversight | N10: Additional SA Oversight | O10: Program Director (IT Workflow - US) | P10: Engagement Manager (IT Workflow - US) | Q10: Project Coordinator (IT Workflow - US) | R10: Chief Business Process Architect (IT Workflow - US) | S10: Business Process Architect (IT Workflow - US) | T10: Business Analyst (IT Workflow - US) | U10: Chief Architect (IT Workflow - US) | V10: Solution Architect (IT Workflow - US) | W10: Platform Architect (IT Workflow - US) | X10: Chief Engineer (IT Workflow - US) | Y10: Lead Engineer (IT Workflow - US) | Z10: Engineer (IT Workflow - US) | AA10: TOTAL (IT Workflow - US) | AB10: Notes (IT Workflow - US) | AC10: Program Director (Customer and Employee Workflow - US) | AD10: Engagement Manager (Customer and Employee Workflow - US) | AE10: Project Coordinator (Customer and Employee Workflow - US) | AF10: Chief Business Process Architect (Customer and Employee Workflow - US) | AG10: Business Process Architect (Customer and Employee Workflow - US) | AH10: Business Analyst (Customer and Employee Workflow - US) | AI10: Chief Architect (Customer and Employee Workflow - US) | AJ10: Solution Architect (Customer and Employee Workflow - US) | AK10: Platform Architect (Customer and Employee Workflow - US) | AL10: Chief Engineer (Customer and Employee Workflow - US) | AM10: Lead Engineer (Customer and Employee Workflow - US) | AN10: Engineer (Customer and Employee Workflow - US) | AO10: TOTAL (Customer and Employee Workflow - US) | AP10: Notes (Customer and Employee Workflow - US) | AQ10: Program Director (IRM / SecOps - US) | AR10: Engagement Manager (IRM / SecOps - US) | AS10: Project Coordinator (IRM / SecOps - US) | AT10: Chief Business Process Architect (IRM / SecOps - US) | AU10: Business Process Architect (IRM / SecOps - US) | AV10: Business Analyst (IRM / SecOps - US) | AW10: Chief Architect (IRM / SecOps - US) | AX10: Solution Architect (IRM / SecOps - US) | AY10: Platform Architect (IRM / SecOps - US) | AZ10: Chief Engineer (IRM / SecOps - US) | BA10: Lead Engineer (IRM / SecOps - US) | BB10: Engineer (IRM / SecOps - US) | BC10: TOTAL (IRM / SecOps - US) | BD10: Notes (Customer and Employee Workflow - US)
B11: INITIATE | AA11: =SUM(Table1456[[#This Row],[Program Director (IT Workflow - US)]:[Engineer (IT Workflow - US)]]) -> 0 | AO11: =SUM(Table1456[[#This Row],[Program Director (Customer and Employee Workflow - US)]:[Engineer (Customer and Employee Workflow - US)]]) -> 0
C12: Initate | D12: Project Set-up | E12: Initial PM introductions, project set-up, and sales to delivery handover. | G12: Chief Architect | H12: Billable - Offshore | I12: 4 | J12: {=INDEX('Client Rates and Roles'!$F$2:$F$433,MATCH(1,COUNTIFS('Opportunity Details'!$C$14,'Client Rates and Roles'!$D$2:$D$433,G12,'Client Rates and Roles'!$B$2:$B$433,H12,'Client Rates and Roles'!$C$2:$C$433,$C$6,'Client Rates and Roles'!$A$2:$A$433),0))} -> #N/A | K12: =I12*J12 -> #N/A | L12: 0 | M12: 20 | N12: 2 | AA12: =SUM(Table1456[[#This Row],[Program Director (IT Workflow - US)]:[Engineer (IT Workflow - US)]]) -> 0 | AO12: =SUM(Table1456[[#This Row],[Program Director (Customer and Employee Workflow - US)]:[Engineer (Customer and Employee Workflow - US)]]) -> 0 | BC12: =SUM(Table1456[[#This Row],[Program Director (IT Workflow - US)]:[Chief Architect (IT Workflow - US)]]) -> 0
C13: Initate | D13: Pre-Engagement Questionnaire | E13: NewRocket will prepare a pre-engagement questionnaire regarding current state of <client>'s platform and vulnerability response program. | F13: • <Client> will be responsible for responding to the pre-engagement questionnaire prior to resource assignment and project kick-off. • <Client> will be responsible for locating the service account owners with access to credentials for any integrations (ex. Scanner). | G13: Architect | H13: Billable - Onshore | I13: 4 | J13: {=INDEX('Client Rates and Roles'!$F$2:$F$433,MATCH(1,COUNTIFS('Opportunity Details'!$C$14,'Client Rates and Roles'!$D$2:$D$433,G13,'Client Rates and Roles'!$B$2:$B$433,H13,'Client Rates and Roles'!$C$2:$C$433,$C$6,'Client Rates and Roles'!$A$2:$A$433),0))} -> #N/A | K13: =I13*J13 -> #N/A | L13: 0 | N13: 2 | AA13: =SUM(Table1456[[#This Row],[Program Director (IT Workflow - US)]:[Engineer (IT Workflow - US)]]) -> 0 | AO13: =SUM(Table1456[[#This Row],[Program Director (Customer and Employee Workflow - US)]:[Engineer (Customer and Employee Workflow - US)]]) -> 0 | BC13: =SUM(Table1456[[#This Row],[Program Director (IT Workflow - US)]:[Chief Architect (IT Workflow - US)]]) -> 0
C14: Initate | D14: Onboard Resources | E14: Project team assigned and coordination with <client> PM to arrange NewRocket access to client's ServiceNow environment(s). | F14: • NewRocket will access Customer’s ServiceNow instance directly from their NewRocket-provided laptops. • NewRocket will not be required to complete any <Client> mandated training. | G14: Practice lead | H14: Billable - Onshore | I14: 4 | J14: {=INDEX('Client Rates and Roles'!$F$2:$F$433,MATCH(1,COUNTIFS('Opportunity Details'!$C$14,'Client Rates and Roles'!$D$2:$D$433,G14,'Client Rates and Roles'!$B$2:$B$433,H14,'Client Rates and Roles'!$C$2:$C$433,$C$6,'Client Rates and Roles'!$A$2:$A$433),0))} -> #N/A | K14: =I14*J14 -> #N/A | L14: 0 | N14: 2 | AA14: =SUM(Table1456[[#This Row],[Program Director (IT Workflow - US)]:[Engineer (IT Workflow - US)]]) -> 0 | AO14: =SUM(Table1456[[#This Row],[Program Director (Customer and Employee Workflow - US)]:[Engineer (Customer and Employee Workflow - US)]]) -> 0 | BC14: =SUM(Table1456[[#This Row],[Program Director (IT Workflow - US)]:[Chief Architect (IT Workflow - US)]]) -> 0
C15: Initate | D15: Project Planning | E15: Co-develop draft project plan between NewRocket and <Client> PM, including review of NewRocket governance process that will be used for project delivery. | G15: Practice lead | H15: Billable - Onshore | I15: 4 | J15: {=INDEX('Client Rates and Roles'!$F$2:$F$433,MATCH(1,COUNTIFS('Opportunity Details'!$C$14,'Client Rates and Roles'!$D$2:$D$433,G15,'Client Rates and Roles'!$B$2:$B$433,H15,'Client Rates and Roles'!$C$2:$C$433,$C$6,'Client Rates and Roles'!$A$2:$A$433),0))} -> #N/A | K15: =I15*J15 -> #N/A | L15: 0 | N15: 2 | AA15: =SUM(Table1456[[#This Row],[Program Director (IT Workflow - US)]:[Engineer (IT Workflow - US)]]) -> 0 | AO15: =SUM(Table1456[[#This Row],[Program Director (Customer and Employee Workflow - US)]:[Engineer (Customer and Employee Workflow - US)]]) -> 0 | BC15: =SUM(Table1456[[#This Row],[Program Director (IT Workflow - US)]:[Chief Architect (IT Workflow - US)]]) -> 0
C16: Initate | D16: Project Kick-Off | E16: Prepare for and conduct formal one (1) hour project kickoff meeting to review goals and objectives, scope, engagement team and initial timeline. | G16: Practice lead | H16: Billable - Onshore | I16: 4 | J16: {=INDEX('Client Rates and Roles'!$F$2:$F$433,MATCH(1,COUNTIFS('Opportunity Details'!$C$14,'Client Rates and Roles'!$D$2:$D$433,G16,'Client Rates and Roles'!$B$2:$B$433,H16,'Client Rates and Roles'!$C$2:$C$433,$C$6,'Client Rates and Roles'!$A$2:$A$433),0))} -> #N/A | K16: =I16*J16 -> #N/A | L16: 0 | N16: 2 | AA16: =SUM(Table1456[[#This Row],[Program Director (IT Workflow - US)]:[Engineer (IT Workflow - US)]]) -> 0 | AO16: =SUM(Table1456[[#This Row],[Program Director (Customer and Employee Workflow - US)]:[Engineer (Customer and Employee Workflow - US)]]) -> 0 | BC16: =SUM(Table1456[[#This Row],[Program Director (IT Workflow - US)]:[Chief Architect (IT Workflow - US)]]) -> 0
B17: PREPARE | AA17: =SUM(Table1456[[#This Row],[Program Director (IT Workflow - US)]:[Engineer (IT Workflow - US)]]) -> 0 | AO17: =SUM(Table1456[[#This Row],[Program Director (Customer and Employee Workflow - US)]:[Engineer (Customer and Employee Workflow - US)]]) -> 0
C18: Prepare | D18: Workshop A | E18: Review of <client>'s response to pre-engagement questionnaire and any processes/artifacts provided as part of the response. | G18: Business Analyst | H18: Billable - Onshore | I18: 40 | J18: {=INDEX('Client Rates and Roles'!$F$2:$F$433,MATCH(1,COUNTIFS('Opportunity Details'!$C$14,'Client Rates and Roles'!$D$2:$D$433,G18,'Client Rates and Roles'!$B$2:$B$433,H18,'Client Rates and Roles'!$C$2:$C$433,$C$6,'Client Rates and Roles'!$A$2:$A$433),0))} -> #N/A | K18: =I18*J18 -> #N/A | L18: 0 | N18: 40 | AA18: =SUM(Table1456[[#This Row],[Program Director (IT Workflow - US)]:[Engineer (IT Workflow - US)]]) -> 0 | AO18: =SUM(Table1456[[#This Row],[Program Director (Customer and Employee Workflow - US)]:[Engineer (Customer and Employee Workflow - US)]]) -> 0 | BC18: =SUM(Table1456[[#This Row],[Program Director (IT Workflow - US)]:[Chief Architect (IT Workflow - US)]]) -> 0
C19: Prepare | D19: Workshop B | E19: Up to a four (4) hour workshop session to review RDSO methodology, current state, and art of the possible focusing on OOTB ServiceNow objects that will be used as part of rapid deployment. | G19: Chief architect | H19: Billable - Offshore | I19: 4 | J19: {=INDEX('Client Rates and Roles'!$F$2:$F$433,MATCH(1,COUNTIFS('Opportunity Details'!$C$14,'Client Rates and Roles'!$D$2:$D$433,G19,'Client Rates and Roles'!$B$2:$B$433,H19,'Client Rates and Roles'!$C$2:$C$433,$C$6,'Client Rates and Roles'!$A$2:$A$433),0))} -> #N/A | K19: =I19*J19 -> #N/A | L19: 0 | N19: 2 | AA19: =SUM(Table1456[[#This Row],[Program Director (IT Workflow - US)]:[Engineer (IT Workflow - US)]]) -> 0 | AO19: =SUM(Table1456[[#This Row],[Program Director (Customer and Employee Workflow - US)]:[Engineer (Customer and Employee Workflow - US)]]) -> 0 | BC19: =SUM(Table1456[[#This Row],[Program Director (IT Workflow - US)]:[Chief Architect (IT Workflow - US)]]) -> 0
C20: Prepare | D20: Workshop C | E20: Develop high-level design approach outlining: • Project outcomes; • Solution assumptions; • ServiceNow objects that will be used to meet the project outcomes; and • Sprint plan to refine detailed requirements. | G20: Consultant | H20: Billable - Offshore | I20: 4 | J20: {=INDEX('Client Rates and Roles'!$F$2:$F$433,MATCH(1,COUNTIFS('Opportunity Details'!$C$14,'Client Rates and Roles'!$D$2:$D$433,G20,'Client Rates and Roles'!$B$2:$B$433,H20,'Client Rates and Roles'!$C$2:$C$433,$C$6,'Client Rates and Roles'!$A$2:$A$433),0))} -> #N/A | K20: =I20*J20 -> #N/A | L20: 0 | N20: 2 | AA20: =SUM(Table1456[[#This Row],[Program Director (IT Workflow - US)]:[Engineer (IT Workflow - US)]]) -> 0 | AO20: =SUM(Table1456[[#This Row],[Program Director (Customer and Employee Workflow - US)]:[Engineer (Customer and Employee Workflow - US)]]) -> 0 | BC20: =SUM(Table1456[[#This Row],[Program Director (IT Workflow - US)]:[Chief Architect (IT Workflow - US)]]) -> 0
C21: Prepare | D21: Finalize Project Plan | E21: Finalize project plan outlining project phases, sprints, and testing timelines. | G21: Consultant | H21: Billable - Onshore | I21: 4 | J21: {=INDEX('Client Rates and Roles'!$F$2:$F$433,MATCH(1,COUNTIFS('Opportunity Details'!$C$14,'Client Rates and Roles'!$D$2:$D$433,G21,'Client Rates and Roles'!$B$2:$B$433,H21,'Client Rates and Roles'!$C$2:$C$433,$C$6,'Client Rates and Roles'!$A$2:$A$433),0))} -> #N/A | K21: =I21*J21 -> #N/A | L21: 0 | N21: 2 | AA21: =SUM(Table1456[[#This Row],[Program Director (IT Workflow - US)]:[Engineer (IT Workflow - US)]]) -> 0 | AO21: =SUM(Table1456[[#This Row],[Program Director (Customer and Employee Workflow - US)]:[Engineer (Customer and Employee Workflow - US)]]) -> 0 | BC21: =SUM(Table1456[[#This Row],[Program Director (IT Workflow - US)]:[Chief Architect (IT Workflow - US)]]) -> 0
C22: Prepare | D22: Develop User Stories/ Story Grooming | E22: Conduct up to meetings to develop user stories and document acceptance criteria. Meetings will run concurrent to the Create stage and topics will be based on sprint plan. | F22: • User Stories and Grooming sessions will follow a pre-defined process and set of draft user stories. There will be up to ten (10) requirements gathering meetings held throughout the sprints focusing on specific topic areas. Each meeting will run between thirty (30) minutes to sixty (60) minutes in duration depending on topic area. <Client> will be expected to ensure appropriate decision makers are including in the meetings to provide requirements. | G22: Consultant | H22: Billable - Onshore | I22: 4 | J22: {=INDEX('Client Rates and Roles'!$F$2:$F$433,MATCH(1,COUNTIFS('Opportunity Details'!$C$14,'Client Rates and Roles'!$D$2:$D$433,G22,'Client Rates and Roles'!$B$2:$B$433,H22,'Client Rates and Roles'!$C$2:$C$433,$C$6,'Client Rates and Roles'!$A$2:$A$433),0))} -> #N/A | K22: =I22*J22 -> #N/A | L22: 0 | N22: 2 | AA22: =SUM(Table1456[[#This Row],[Program Director (IT Workflow - US)]:[Engineer (IT Workflow - US)]]) -> 0 | AO22: =SUM(Table1456[[#This Row],[Program Director (Customer and Employee Workflow - US)]:[Engineer (Customer and Employee Workflow - US)]]) -> 0 | BC22: =SUM(Table1456[[#This Row],[Program Director (IT Workflow - US)]:[Chief Architect (IT Workflow - US)]]) -> 0
B23: EXECUTE | AA23: =SUM(Table1456[[#This Row],[Program Director (IT Workflow - US)]:[Engineer (IT Workflow - US)]]) -> 0 | AO23: =SUM(Table1456[[#This Row],[Program Director (Customer and Employee Workflow - US)]:[Engineer (Customer and Employee Workflow - US)]]) -> 0
C24: Execute | D24: Install Plugins | E24: Install and enable OOTB Security Operations and Vulnerability Response plugin applications in all environments. | F24: • This implementation assumes that all VR configuration will be completed using OOTB configuration options and no scripted solutions will be developed. • <Client> is responsible for ensuring platform and solution plugins versions are the same in all environments. | G24: Consultant | H24: Billable - Offshore | I24: 4 | J24: {=INDEX('Client Rates and Roles'!$F$2:$F$433,MATCH(1,COUNTIFS('Opportunity Details'!$C$14,'Client Rates and Roles'!$D$2:$D$433,G24,'Client Rates and Roles'!$B$2:$B$433,H24,'Client Rates and Roles'!$C$2:$C$433,$C$6,'Client Rates and Roles'!$A$2:$A$433),0))} -> #N/A | K24: =I24*J24 -> #N/A | L24: 0 | N24: 2 | AA24: =SUM(Table1456[[#This Row],[Program Director (IT Workflow - US)]:[Engineer (IT Workflow - US)]]) -> 0 | AO24: =SUM(Table1456[[#This Row],[Program Director (Customer and Employee Workflow - US)]:[Engineer (Customer and Employee Workflow - US)]]) -> 0 | BC24: =SUM(Table1456[[#This Row],[Program Director (IT Workflow - US)]:[Chief Architect (IT Workflow - US)]]) -> 0
C25: Execute | D25: TBC (Scanner) Integration | E25: Document and perform default installation and configuration for TBC (Scanner) integration available from ServiceNow Store. Review scanned assets to ensure proper connection to ServiceNow. | F25: • Integration will be a Store provided Scanner integration with no customization. If MID servers are required for integrations, then they will be provided and managed by <Client>. • <Client> is responsible for owning and managing the Scanner. NewRocket is not responsible for troubleshooting any issues with the Scanner and ServiceNow. • To map vulnerabilities in lower environments, <Client> will be responsible for ensuring sample vulnerabilities are available in lower environments by either setting up a DEV/TEST instance of the Scanner or bringing sample PROD events to the lower environments. • <Client> will be responsible for ensuring DEV/TEST is populated with scannable CIs related to the scanner that will be connected to each environment. | G25: Consultant | H25: Billable - Onshore | I25: 4 | J25: {=INDEX('Client Rates and Roles'!$F$2:$F$433,MATCH(1,COUNTIFS('Opportunity Details'!$C$14,'Client Rates and Roles'!$D$2:$D$433,G25,'Client Rates and Roles'!$B$2:$B$433,H25,'Client Rates and Roles'!$C$2:$C$433,$C$6,'Client Rates and Roles'!$A$2:$A$433),0))} -> #N/A | K25: =I25*J25 -> #N/A | L25: 0 | N25: 2 | AA25: =SUM(Table1456[[#This Row],[Program Director (IT Workflow - US)]:[Engineer (IT Workflow - US)]]) -> 0 | AO25: =SUM(Table1456[[#This Row],[Program Director (Customer and Employee Workflow - US)]:[Engineer (Customer and Employee Workflow - US)]]) -> 0 | BC25: =SUM(Table1456[[#This Row],[Program Director (IT Workflow - US)]:[Chief Architect (IT Workflow - US)]]) -> 0
C26: Execute | D26: CMDB Attribute / CI Matching | E26: Review CMDB attributes for availability. Document and configure CI Matching/Look-up Rules. | F26: • FQDN and/or IP Address and/or NetBIOS and/or Name is populated in the CMDB and can be matched with scanner results for all scannable assets. NewRocket is not responsible for populating or updating the CMDB. • <Client> is responsible for identifying the attributes that will be used to support CI matching and look up. NewRocket is not responsible for analysing assets to increase match rate or advising or providing reccomendations on how to improve it. • Active IP management is out of scope for this engagement. If <Client> is using DHCP then additional effort will be required. **ANYTHING ELSE WE WANT TO INCLUDE TO PROTECT US???***** | G26: Architect | H26: Billable - Onshore | I26: 4 | J26: {=INDEX('Client Rates and Roles'!$F$2:$F$433,MATCH(1,COUNTIFS('Opportunity Details'!$C$14,'Client Rates and Roles'!$D$2:$D$433,G26,'Client Rates and Roles'!$B$2:$B$433,H26,'Client Rates and Roles'!$C$2:$C$433,$C$6,'Client Rates and Roles'!$A$2:$A$433),0))} -> #N/A | K26: =I26*J26 -> #N/A | L26: 0 | N26: 2 | AA26: =SUM(Table1456[[#This Row],[Program Director (IT Workflow - US)]:[Engineer (IT Workflow - US)]]) -> 0 | AO26: =SUM(Table1456[[#This Row],[Program Director (Customer and Employee Workflow - US)]:[Engineer (Customer and Employee Workflow - US)]]) -> 0 | BC26: =SUM(Table1456[[#This Row],[Program Director (IT Workflow - US)]:[Chief Architect (IT Workflow - US)]]) -> 0
C27: Execute | D27: Permissions, Roles and Groups | E27: Review and document OOTB roles and permissions that will be used to populate <client> defined groups. | F27: • OOTB roles will be leveraged to populate client defined groups with no permission changes or custom access model. | G27: Consultant | H27: Billable - Onshore | I27: 4 | J27: {=INDEX('Client Rates and Roles'!$F$2:$F$433,MATCH(1,COUNTIFS('Opportunity Details'!$C$14,'Client Rates and Roles'!$D$2:$D$433,G27,'Client Rates and Roles'!$B$2:$B$433,H27,'Client Rates and Roles'!$C$2:$C$433,$C$6,'Client Rates and Roles'!$A$2:$A$433),0))} -> #N/A | K27: =I27*J27 -> #N/A | L27: 0 | N27: 2 | AA27: =SUM(Table1456[[#This Row],[Program Director (IT Workflow - US)]:[Engineer (IT Workflow - US)]]) -> 0 | AO27: =SUM(Table1456[[#This Row],[Program Director (Customer and Employee Workflow - US)]:[Engineer (Customer and Employee Workflow - US)]]) -> 0 | BC27: =SUM(Table1456[[#This Row],[Program Director (IT Workflow - US)]:[Chief Architect (IT Workflow - US)]]) -> 0
C28: Execute | D28: Vulnerability Assignment Rules | E28: Document and configure vulnerability assignment rules. | F28: • <Client> understands their internal RACI matrix required to support their vulnerability response program including assignment and grouping. • Up to three (3) assignment rules will be configured. | G28: Consultant | H28: Billable - Onshore | I28: 4 | J28: {=INDEX('Client Rates and Roles'!$F$2:$F$433,MATCH(1,COUNTIFS('Opportunity Details'!$C$14,'Client Rates and Roles'!$D$2:$D$433,G28,'Client Rates and Roles'!$B$2:$B$433,H28,'Client Rates and Roles'!$C$2:$C$433,$C$6,'Client Rates and Roles'!$A$2:$A$433),0))} -> #N/A | K28: =I28*J28 -> #N/A | L28: 0 | N28: 2 | AA28: =SUM(Table1456[[#This Row],[Program Director (IT Workflow - US)]:[Engineer (IT Workflow - US)]]) -> 0 | AO28: =SUM(Table1456[[#This Row],[Program Director (Customer and Employee Workflow - US)]:[Engineer (Customer and Employee Workflow - US)]]) -> 0 | BC28: =SUM(Table1456[[#This Row],[Program Director (IT Workflow - US)]:[Chief Architect (IT Workflow - US)]]) -> 0
C29: Execute | D29: Vulnerability Grouping | E29: Document and configure vulnerability grouping rules. | F29: • Up to three (3) grouping rules will be configured. | G29: Consultant | H29: Billable - Onshore | I29: 4 | J29: {=INDEX('Client Rates and Roles'!$F$2:$F$433,MATCH(1,COUNTIFS('Opportunity Details'!$C$14,'Client Rates and Roles'!$D$2:$D$433,G29,'Client Rates and Roles'!$B$2:$B$433,H29,'Client Rates and Roles'!$C$2:$C$433,$C$6,'Client Rates and Roles'!$A$2:$A$433),0))} -> #N/A | K29: =I29*J29 -> #N/A | L29: 0 | N29: 2 | AA29: =SUM(Table1456[[#This Row],[Program Director (IT Workflow - US)]:[Engineer (IT Workflow - US)]]) -> 0 | AO29: =SUM(Table1456[[#This Row],[Program Director (Customer and Employee Workflow - US)]:[Engineer (Customer and Employee Workflow - US)]]) -> 0 | BC29: =SUM(Table1456[[#This Row],[Program Director (IT Workflow - US)]:[Chief Architect (IT Workflow - US)]]) -> 0
C30: Execute | D30: Vulnerability Risk Scoring | E30: Document CMDB and Scanner fields to be leveraged as part of risk scoring calculation. Utilize OOB functionality to develop risk score calculation. | F30: • <Client> will provide parameters that will be used for risk score calculation and ensure values are available within ServiceNow. • One (1) risk score calculation will be configured using available values using drop down configuration (non-scripted). Up to five (5) variables will be considered in the scoring logic. • CVSS environmental or temporal scoring is not used as part of the risk score calculation. | G30: Consultant | H30: Billable - Onshore | I30: 4 | J30: {=INDEX('Client Rates and Roles'!$F$2:$F$433,MATCH(1,COUNTIFS('Opportunity Details'!$C$14,'Client Rates and Roles'!$D$2:$D$433,G30,'Client Rates and Roles'!$B$2:$B$433,H30,'Client Rates and Roles'!$C$2:$C$433,$C$6,'Client Rates and Roles'!$A$2:$A$433),0))} -> #N/A | K30: =I30*J30 -> #N/A | L30: 0 | N30: 2 | AA30: =SUM(Table1456[[#This Row],[Program Director (IT Workflow - US)]:[Engineer (IT Workflow - US)]]) -> 0 | AO30: =SUM(Table1456[[#This Row],[Program Director (Customer and Employee Workflow - US)]:[Engineer (Customer and Employee Workflow - US)]]) -> 0 | BC30: =SUM(Table1456[[#This Row],[Program Director (IT Workflow - US)]:[Chief Architect (IT Workflow - US)]]) -> 0
C31: Execute | D31: Exceptions and Deferral Management | E31: Document and utilize OOTB VR exception management process. | F31: • OOTB VR exception management process using two levels of approvals will be utilized. • The Exception approval process uses the VR solution version of exception management not IRM. | G31: Consultant | H31: Billable - Onshore | I31: 4 | J31: {=INDEX('Client Rates and Roles'!$F$2:$F$433,MATCH(1,COUNTIFS('Opportunity Details'!$C$14,'Client Rates and Roles'!$D$2:$D$433,G31,'Client Rates and Roles'!$B$2:$B$433,H31,'Client Rates and Roles'!$C$2:$C$433,$C$6,'Client Rates and Roles'!$A$2:$A$433),0))} -> #N/A | K31: =I31*J31 -> #N/A | L31: 0 | N31: 2 | AA31: =SUM(Table1456[[#This Row],[Program Director (IT Workflow - US)]:[Engineer (IT Workflow - US)]]) -> 0 | AO31: =SUM(Table1456[[#This Row],[Program Director (Customer and Employee Workflow - US)]:[Engineer (Customer and Employee Workflow - US)]]) -> 0 | BC31: =SUM(Table1456[[#This Row],[Program Director (IT Workflow - US)]:[Chief Architect (IT Workflow - US)]]) -> 0
C32: Execute | D32: Change Management | E32: Document and utilize OOTB change management process. | F32: • No changes will be made to ServiceNow Change management solution. • If <Client>is currently utilizing or has made changes to the change management solution it is assumed that any changes will work with the OOTB VR solution.<Client> will be responsible for troubleshooting and resolving and issues. | G32: Consultant | H32: Billable - Onshore | I32: 4 | J32: {=INDEX('Client Rates and Roles'!$F$2:$F$433,MATCH(1,COUNTIFS('Opportunity Details'!$C$14,'Client Rates and Roles'!$D$2:$D$433,G32,'Client Rates and Roles'!$B$2:$B$433,H32,'Client Rates and Roles'!$C$2:$C$433,$C$6,'Client Rates and Roles'!$A$2:$A$433),0))} -> #N/A | K32: =I32*J32 -> #N/A | L32: 0 | N32: 2 | AA32: =SUM(Table1456[[#This Row],[Program Director (IT Workflow - US)]:[Engineer (IT Workflow - US)]]) -> 0 | AO32: =SUM(Table1456[[#This Row],[Program Director (Customer and Employee Workflow - US)]:[Engineer (Customer and Employee Workflow - US)]]) -> 0 | BC32: =SUM(Table1456[[#This Row],[Program Director (IT Workflow - US)]:[Chief Architect (IT Workflow - US)]]) -> 0
C33: Execute | D33: Notifications and SLA's | E33: Document and configure notifications and SLA's | F33: • Up to three (3) new notifications will be configured using OOTB configuration options (no scripted solution) and no custom email templates. • Up to two (2) SLA will be configured using OOTB configuration options (no scripted solution). | G33: Consultant | H33: Billable - Offshore | I33: 800 | J33: {=INDEX('Client Rates and Roles'!$F$2:$F$433,MATCH(1,COUNTIFS('Opportunity Details'!$C$14,'Client Rates and Roles'!$D$2:$D$433,G33,'Client Rates and Roles'!$B$2:$B$433,H33,'Client Rates and Roles'!$C$2:$C$433,$C$6,'Client Rates and Roles'!$A$2:$A$433),0))} -> #N/A | K33: =I33*J33 -> #N/A | L33: 0 | N33: 2 | AA33: =SUM(Table1456[[#This Row],[Program Director (IT Workflow - US)]:[Engineer (IT Workflow - US)]]) -> 0 | AO33: =SUM(Table1456[[#This Row],[Program Director (Customer and Employee Workflow - US)]:[Engineer (Customer and Employee Workflow - US)]]) -> 0 | BC33: =SUM(Table1456[[#This Row],[Program Director (IT Workflow - US)]:[Chief Architect (IT Workflow - US)]]) -> 0
C34: Execute | D34: Dashboards and Reports | E34: Review the OOB dashboards and complete minor updates to filters for the standard dashboards, as well as enable the Performance Analytics dashboards. | F34: • No new dashboards and reports will be created as part of the SIR implementation. <Client> will leverage the OOB dashboards and reports with minor tuning of filters. If licensing permits, NewRocket will enable the OOB Performance Analytics dashboards without changes. | G34: Consultant | H34: Billable - Onshore | I34: 400 | J34: {=INDEX('Client Rates and Roles'!$F$2:$F$433,MATCH(1,COUNTIFS('Opportunity Details'!$C$14,'Client Rates and Roles'!$D$2:$D$433,G34,'Client Rates and Roles'!$B$2:$B$433,H34,'Client Rates and Roles'!$C$2:$C$433,$C$6,'Client Rates and Roles'!$A$2:$A$433),0))} -> #N/A | K34: =I34*J34 -> #N/A | L34: 0 | N34: 2 | AA34: =SUM(Table1456[[#This Row],[Program Director (IT Workflow - US)]:[Engineer (IT Workflow - US)]]) -> 0 | AO34: =SUM(Table1456[[#This Row],[Program Director (Customer and Employee Workflow - US)]:[Engineer (Customer and Employee Workflow - US)]]) -> 0 | BC34: =SUM(Table1456[[#This Row],[Program Director (IT Workflow - US)]:[Chief Architect (IT Workflow - US)]]) -> 0
C35: Execute | D35: Sprint Demos | E35: Conduct end of sprint demos to show functionality. | F35: •There will be up to four (4) sprint demos and will be one (1) hour in duration per demo. | G35: Consultant | H35: Billable - Onshore | I35: 4 | J35: {=INDEX('Client Rates and Roles'!$F$2:$F$433,MATCH(1,COUNTIFS('Opportunity Details'!$C$14,'Client Rates and Roles'!$D$2:$D$433,G35,'Client Rates and Roles'!$B$2:$B$433,H35,'Client Rates and Roles'!$C$2:$C$433,$C$6,'Client Rates and Roles'!$A$2:$A$433),0))} -> #N/A | K35: =I35*J35 -> #N/A | L35: 0 | N35: 2 | AA35: =SUM(Table1456[[#This Row],[Program Director (IT Workflow - US)]:[Engineer (IT Workflow - US)]]) -> 0 | AO35: =SUM(Table1456[[#This Row],[Program Director (Customer and Employee Workflow - US)]:[Engineer (Customer and Employee Workflow - US)]]) -> 0 | BC35: =SUM(Table1456[[#This Row],[Program Director (IT Workflow - US)]:[Chief Architect (IT Workflow - US)]]) -> 0
C36: Execute | D36: Unit Testing | E36: Complete unit testing against NewRocket configured items. | G36: Consultant | H36: Billable - Onshore | I36: 4 | J36: {=INDEX('Client Rates and Roles'!$F$2:$F$433,MATCH(1,COUNTIFS('Opportunity Details'!$C$14,'Client Rates and Roles'!$D$2:$D$433,G36,'Client Rates and Roles'!$B$2:$B$433,H36,'Client Rates and Roles'!$C$2:$C$433,$C$6,'Client Rates and Roles'!$A$2:$A$433),0))} -> #N/A | K36: =I36*J36 -> #N/A | L36: 0 | N36: 2 | AA36: =SUM(Table1456[[#This Row],[Program Director (IT Workflow - US)]:[Engineer (IT Workflow - US)]]) -> 0 | AO36: =SUM(Table1456[[#This Row],[Program Director (Customer and Employee Workflow - US)]:[Engineer (Customer and Employee Workflow - US)]]) -> 0 | BC36: =SUM(Table1456[[#This Row],[Program Director (IT Workflow - US)]:[Chief Architect (IT Workflow - US)]]) -> 0
B37: DELIVER | AA37: =SUM(Table1456[[#This Row],[Program Director (IT Workflow - US)]:[Engineer (IT Workflow - US)]]) -> 0 | AO37: =SUM(Table1456[[#This Row],[Program Director (Customer and Employee Workflow - US)]:[Engineer (Customer and Employee Workflow - US)]]) -> 0
C38: Deliver | D38: UAT Environment deployment | E38: Develop a system deployment plan and support the migration of five (5) releases to the UAT environment. | F38: • NewRocket will release configured solution to the UAT environment at the end of each sprint and once at the end of UAT. • <Client> will be responsible for QA and UAT testing during the sprint cycles and provide any feedback within one (1) week of deployment to UAT. • NewRocket assumes UAT will be staffed by one resource. Additional resources will decrease the duration of UAT or will result in a Change Request. | G38: Consultant | H38: Billable - Onshore | I38: 4 | J38: {=INDEX('Client Rates and Roles'!$F$2:$F$433,MATCH(1,COUNTIFS('Opportunity Details'!$C$14,'Client Rates and Roles'!$D$2:$D$433,G38,'Client Rates and Roles'!$B$2:$B$433,H38,'Client Rates and Roles'!$C$2:$C$433,$C$6,'Client Rates and Roles'!$A$2:$A$433),0))} -> #N/A | K38: =I38*J38 -> #N/A | L38: 0 | N38: 2 | AA38: =SUM(Table1456[[#This Row],[Program Director (IT Workflow - US)]:[Engineer (IT Workflow - US)]]) -> 0 | AO38: =SUM(Table1456[[#This Row],[Program Director (Customer and Employee Workflow - US)]:[Engineer (Customer and Employee Workflow - US)]]) -> 0 | BC38: =SUM(Table1456[[#This Row],[Program Director (IT Workflow - US)]:[Chief Architect (IT Workflow - US)]]) -> 0
C39: Deliver | D39: UAT Support - Onshore | E39: Review and resolve NewRocket configuration defects during UAT testing. | F39: • NewRocket is not responsible for reviewing and resolving platform related defects. <Client>'s platform team will be responsible for raising and resolving ServiceNow defects directly with ServiceNow. | G39: Consultant - UAT | H39: Billable - Onshore | I39: =MROUND(SUMIFS(Table1456[Hours],Table1456[Project Role],"Consultant",Table1456[Billable/ Non-Billable],"Billable - Onshore",Table1456[Task],"<>UAT Support - Onshore")*0.2,4) -> 108 | J39: {=INDEX('Client Rates and Roles'!$F$2:$F$433,MATCH(1,COUNTIFS('Opportunity Details'!$C$14,'Client Rates and Roles'!$D$2:$D$433,G39,'Client Rates and Roles'!$B$2:$B$433,H39,'Client Rates and Roles'!$C$2:$C$433,$C$6,'Client Rates and Roles'!$A$2:$A$433),0))} -> #N/A | K39: =I39*J39 -> #N/A | M39: 40 | AA39: =SUM(Table1456[[#This Row],[Program Director (IT Workflow - US)]:[Engineer (IT Workflow - US)]]) -> 0 | AO39: =SUM(Table1456[[#This Row],[Program Director (Customer and Employee Workflow - US)]:[Engineer (Customer and Employee Workflow - US)]]) -> 0
C40: Deliver | D40: UAT Support - Offshore | E40: Review and resolve NewRocket configuration defects during UAT testing. | F40: • NewRocket is not responsible for reviewing and resolving platform related defects. <Client>'s platform team will be responsible for raising and resolving ServiceNow defects directly with ServiceNow. | G40: Consultant - UAT | H40: Billable - Offshore | I40: =MROUND(SUMIFS(Table1456[Hours],Table1456[Project Role],"Consultant",Table1456[Billable/ Non-Billable],"Billable - Offshore",Table1456[Task],"<>UAT Support - Onshore")*0.2,4) -> 164 | J40: {=INDEX('Client Rates and Roles'!$F$2:$F$433,MATCH(1,COUNTIFS('Opportunity Details'!$C$14,'Client Rates and Roles'!$D$2:$D$433,G40,'Client Rates and Roles'!$B$2:$B$433,H40,'Client Rates and Roles'!$C$2:$C$433,$C$6,'Client Rates and Roles'!$A$2:$A$433),0))} -> #N/A | K40: =I40*J40 -> #N/A | L40: 2 | M40: 3 | N40: 2 | AA40: =SUM(Table1456[[#This Row],[Program Director (IT Workflow - US)]:[Engineer (IT Workflow - US)]]) -> 0 | AO40: =SUM(Table1456[[#This Row],[Program Director (Customer and Employee Workflow - US)]:[Engineer (Customer and Employee Workflow - US)]]) -> 0 | BC40: =SUM(Table1456[[#This Row],[Program Director (IT Workflow - US)]:[Chief Architect (IT Workflow - US)]]) -> 0
C41: Deliver | D41: Production deployment | E41: Update the system deployment plan and support the migration of one (1) release to the Production environment. | G41: Consultant | H41: Billable - Onshore | I41: 4 | J41: {=INDEX('Client Rates and Roles'!$F$2:$F$433,MATCH(1,COUNTIFS('Opportunity Details'!$C$14,'Client Rates and Roles'!$D$2:$D$433,G41,'Client Rates and Roles'!$B$2:$B$433,H41,'Client Rates and Roles'!$C$2:$C$433,$C$6,'Client Rates and Roles'!$A$2:$A$433),0))} -> #N/A | K41: =I41*J41 -> #N/A | L41: 0 | AA41: =SUM(Table1456[[#This Row],[Program Director (IT Workflow - US)]:[Engineer (IT Workflow - US)]]) -> 0 | AO41: =SUM(Table1456[[#This Row],[Program Director (Customer and Employee Workflow - US)]:[Engineer (Customer and Employee Workflow - US)]]) -> 0 | BC41: =SUM(Table1456[[#This Row],[Program Director (IT Workflow - US)]:[Chief Architect (IT Workflow - US)]]) -> 0
...

Sheet Candace Working Notes
A1: To Do, Working Notes and Ideas:
B2: Instructions Tab - To be completed at the end.
B3: Opportunity Details - Need to review with SalesForce to avoid duplication of effort - Access Pending
B4: Opportunity Details - Need to validate currencies
B5: Opportunity Details - Need to validate contract types
B6: Opportunity Details - Need to validate if we have a select group of approved partners. Do we need a process for partner approvals?
B7: Opportunity Details - Need to confirm the list of use cases/ offerings - Validate against sales force.
B8: Opportunity Details - Review risk assessment process - Do we want to add in controls that indicate minimum requirements for mark up, governance review etc.
B9: Estimate - Add estimate for each use case once final template is agreed to
B10: Estimate - Finalize client facing roles
B11: Estimate - How do we want to handle PM, BA and Admin - Standard % that gets applied at the end?
B12: Pricing Tool - Review opportinity to integrate the pricing tool into this spreadsheet. Lock down sheet for only certain users.

Sheet INSTRUCTIONS
A1: Instructions
A2: Version 2.07
A3: Release Date: 2025-08-29
A5: 1. There are 3 quoting files in this template (Managed Services, Staff Aug/Change Order, Manticore for PS quoting with tasks), choose which one you are using.
A6: 2. If you are not using the Managed Services file, go to the MS Pricing sheet and put 0 for "Number of hours per month" and then hide the pink sheets. This will ensure the Deal review dashboard doesn't pull in the template's financials.
A7: 3. If you are not using the Staff Aug/Change Order tab, hide those purple tabs.
A8: 4. If you are not using the manticore for PS quoting with tasks, hide all blue tabs and clear out the hours in the sheets.
A9: 5. In the end, you should have the tabs visible for which you are quoting, this will help ensure Deal review reviews the correct data.
A10: 6. Now go to the respective sections and follow the instructions on the home page (1st tab) of each color coded section.

Sheet Managed Services -->
A1: Instructions
A2: Version 2.0
A3: Release Date: 2024-06-10
A5: 1. Copy this file from SharePoint and place in the Customer's Client Focus folder for this respective Opportunity/Project.
A6: 2. Select the Managed Services options and enter the # of hours per month and term, this will automatically set the resource locations.
A7: 3. Fill out the role locations on the Pricing tab.

Sheet MS - Deal Review Guidance
B6: Strategists are accountable for ensuring the deal can be delivered as written and the delivery model and scope aligns to effort and roles required. ​
B7: Standard SOW template used ​
B8: Supported modules listed​
B9: Beneficial rate and hours in table and description of services ​
B10: Check for any changes to subscription management understandings​
B11: Pricing file matches offering (roles, location, beneficial rate, margin)​
B12: Evolve entitlement sufficient to delivery project work – 300 + hrs. per/month ​
B13: Evolve scope includes initial focus and/or advisory/roadmap to initiate service ​
B14: ​
B15: Deal Desk is accountable for:​
B16: Pricing file, term, invoice schedule ++.​
B17: MSA date being added to SOW​
... B30: ​

Sheet MS Pricing
B2: NewRocket Managed Services Pricing Tool
B3: Internal Use Only
B6: Engagement Overview | O6: ="Financial Dashboard (" &G17& ")" -> Financial Dashboard (GBP)
B7: Date | P7: Total | Q7: Onsite | R7: India
B8: Preparer's Name | O8: Revenue | P8: =AL58 -> 238800 | Q8: =AM58 -> 124176 | R8: =AN58 -> 114624
B9: Practice | G9: Managed Services | O9: Cost | P9: =AO58 -> 78088.67 | Q9: =AP58 -> 68499.73 | R9: =AQ58 -> 9588.9406
B10: Capability | G10: Technology: Platform | O10: GM/GP | P10: =P8-P9 -> 160711.33 | Q10: =Q8-Q9 -> 55676.27 | R10: =R8-R9 -> 105035.06 | AA10: Minimum total CM% based on India leverage
B11: Account Name | O11: GM% | P11: =IFERROR(P10/P8,"") -> 0.67299552 | Q11: =IFERROR(Q10/Q8,"") -> 0.44836579 | R11: =IFERROR(R10/R8,"") -> 0.91634439 | AA11: =0.3125*R13^5-0.4276*R13^4+0.3734*R13^3-0.1274*R13^2+0.0669*R13+0.5 -> 0.52931793
B12: Partner | O12: Hours | P12: =IFERROR(J61,0) -> 1200 | Q12: =IFERROR(AS58+AU58,"") -> 624 | R12: =IFERROR(AT58+AV58,"") -> 576
B13: Opportunity Name | O13: Hours % | P13: =IFERROR(P12/P12,"") -> 1 | Q13: =IFERROR(Q12/P12,"") -> 0.52 | R13: =IFERROR(R12/P12,"") -> 0.48
B14: Opportunity Owner | O14: Avg Rate | P14: =IFERROR(P8/P12,"") -> 199 | Q14: =IFERROR(Q8/Q12,"") -> 199 | R14: =IFERROR(R8/R12,"") -> 199
B15: Salesforce Opportunity Number | O15: Avg Rack | P15: =IFERROR(AF58/AR58,"") -> 110.5 | Q15: =IFERROR(AG58/AS58,"") -> 154.57692 | R15: =IFERROR(AH58/AT58,"") -> 62.75
B16: Client Location | G16: UK | O16: Variance | P16: =IFERROR(P14-P15,"") -> 88.5 | Q16: =IFERROR(Q14-Q15,"") -> 44.423077 | R16: =IFERROR(R14-R15,"") -> 136.25 | AA16: Percentage for CM calculation
B17: Opportunity Currency | G17: =IFERROR(VLOOKUP(G16,'Lists (2)'!C2:D6,2),"") -> GBP | O17: Variance % | P17: =IFERROR(P16/P15,"") -> 0.80090498 | Q17: =IFERROR(Q16/Q15,"") -> 0.28738492 | R17: =IFERROR(R16/R15,"") -> 2.1713147 | AA17: 0.25
B18: Contract Type | G18: Fixed Price | O18: CM% | P18: =IFERROR(P10/P8-($AA$17),"") -> 0.42299552 | Q18: =IFERROR(Q10/Q8-($AA$17),"") -> 0.19836579 | R18: =IFERROR(R10/R8-($AA$17),"") -> 0.66634439
B19: Change Order | G19: No | AA19: Location of Resource Ration Lookup
B20: Contract Details | O20: CodeWorks Cost | R20: =IF($G$25="Yes",IF(1*($P$58*0.01)>2000,(-1*($P$58*0.01)),-2000),"0") -> -2388 | AA20: {=_xlfn.IFS($G$24="Operate",1,$G$24="Enhance",2,$G$24="Operate & Enhance",3,$G$24="Hypercare",4)} -> 3
B21: Number of Hours per month | G21: 100 | O21: Total Margin after CodeWorks | R21: =IFERROR(SUM(P10,R20)/R22,"") -> 0.66969244
B22: Number of Months | G22: 12 | O22: Total Revenue after CodeWorks | R22: =SUM(P58,R20) -> 236412
B23: Beneficial Rate | G23: 199
B24: Offering being Sold | G24: Operate & Enhance
B25: Price in CodeWorks? (override by changing value) | G25: {=_xlfn.IFS($G$24="Enhance","Yes",$G$24="Operate & Enhance","Yes",$G$24="Operate","No",$G$24="Hypercare","No")} -> Yes | O25: Guidance
B26: Notes | O26: Scott will fill this in when identified rules for margin/thresholds For Resource locations, leave as-is unless approval from Veronica to offshore more resources. If client cannot accommodate Global resourcing, you can onshore all roles if you have a necessity to do so but this will likely have a higher benefical rate requirement. For Hypercare, change the engineer to where the engineer is located on the project sold.
B27: If there are any staffing restrictions, enter them here:
B28: Notes
B31: Roles and Rates
B32: Bill Rate: Onshore/ Offshore | C32: Billing Location | D32: Resource Location (Margin) | E32: Role Name | J32: Hours | L32: Rack Bill Rate | M32: Discount or Premium | N32: Bill Rate | O32: Cost Rate | P32: Revenue | Q32: Cost | R32: GM/GP | S32: GM% | T32: Practice | U32: Skill #1 | V32: Skill #2 | W32: Skill #3 | X32: % of hours for MS | Y32: Note | AA32: India? | AB32: Advisory? | AC32: Role | AD32: Rack Bill Rate | AE32: Cost Rate | AF32: Total Revenue at Rack Rate | AG32: Onsite Revenue at Rack Rate | AH32: India Revenue at Rack Rate | AI32: Revenue w/ Contingency | AJ32: Cost w/ Contingency | AK32: One-Time Discount | AL32: Total Revenue | AM32: Onsite Revenue | AN32: India Revenue | AO32: Total Cost | AP32: Onsite Cost | AQ32: India Cost | AR32: Total Hours | AS32: Onsite Hours | AT32: India Hours | AU32: Onsite Contingency Hours | AV32: India Contingency Hours
B33: Onshore | C33: {=IFERROR(_xlfn.IFS(B33="Onshore",$G$16,B33="Offshore","India"),"")} -> UK | D33: UK | E33: MS - Architect | J33: =ROUND($G$21*$G$22*X33,0) -> 180 | L33: =IFERROR(INDEX(Bill_Rates!$L:$L,MATCH('MS Pricing'!$AD33,Bill_Rates!$J:$J,0)),"") -> 169 | M33: =$G$23-L33 -> 30 | N33: =IFERROR(L33+M33,"") -> 199 | O33: =IFERROR(INDEX(Bill_Rates!$O:$O,MATCH($AE33,Bill_Rates!$J:$J,0)),"") -> 106 | P33: =IFERROR(N33*J33,"") -> 35820 | Q33: =IFERROR((J33+K33)*O33,"") -> 19080 | R33: =IFERROR(P33-Q33,"") -> 16740 | S33: =IFERROR(R33/P33,"") -> 0.46733668 | T33: Managed Services | X33: {=INDEX('MS Lookups'!B1:E20,2,'MS Pricing'!AA20)} -> 0.15 | AB33: =IF(OR(G33="Change Management",G33="Enablement",G33="Strategy"),G33,"") | AC33: =E33 -> MS - Architect | AD33: =G$16&C33&AA33&F33&AB33&H33&E33 -> UKUKMS - Architect | AE33: =G$16&D33&H33&E33 -> UKUKMS - Architect | AF33: =IFERROR(L33*J33,"") -> 30420 | AG33: =IFERROR(AF33-AH33,"") -> 30420 | AH33: =IF(D33="India",AF33,0) -> 0 | AI33: =IFERROR(P33+P33/$P$58*$P$59,"") -> 35820 | AJ33: =IFERROR(Q33+Q33/$Q$58*$Q$59,"") -> 19080 | AK33: =IFERROR(P33/$P$58*$P$60,"") -> 0 | AL33: =IFERROR(AI33+AK33,"") -> 35820 | AM33: =IFERROR(AL33-AN33,"") -> 35820 | AN33: =IF(D33="India",AL33,0) -> 0 | AO33: =AJ33 -> 19080 | AP33: =IFERROR(AO33-AQ33,"") -> 19080 | AQ33: =IF(D33="India",AO33,0) -> 0
B34: Onshore | C34: {=IFERROR(_xlfn.IFS(B34="Onshore",$G$16,B34="Offshore","India"),"")} -> UK | D34: USA | E34: MS - Engineer | J34: =ROUND($G$21*$G$22*X34,0) -> 300 | L34: =IFERROR(INDEX(Bill_Rates!$L:$L,MATCH('MS Pricing'!$AD34,Bill_Rates!$J:$J,0)),"") -> 139 | M34: =$G$23-L34 -> 60 | N34: =IFERROR(L34+M34,"") -> 199 | O34: =IFERROR(INDEX(Bill_Rates!$O:$O,MATCH($AE34,Bill_Rates!$J:$J,0)),"") -> 107.2436 | P34: =IFERROR(N34*J34,"") -> 59700 | Q34: =IFERROR((J34+K34)*O34,"") -> 32173.08 | R34: =IFERROR(P34-Q34,"") -> 27526.92 | S34: =IFERROR(R34/P34,"") -> 0.46108744 | T34: Managed Services | X34: {=INDEX('MS Lookups'!B1:E20,3,'MS Pricing'!AA20)} -> 0.25 | AB34: =IF(OR(G34="Change Management",G34="Enablement",G34="Strategy"),G34,"") | AC34: =E34 -> MS - Engineer | AD34: =G$16&C34&AA34&F34&AB34&H34&E34 -> UKUKMS - Engineer | AE34: =G$16&D34&H34&E34 -> UKUSAMS - Engineer | AF34: =IFERROR(L34*J34,"") -> 41700 | AG34: =IFERROR(AF34-AH34,"") -> 41700 | AH34: =IF(D34="India",AF34,0) -> 0 | AI34: =IFERROR(P34+P34/$P$58*$P$59,"") -> 59700 | AJ34: =IFERROR(Q34+Q34/$Q$58*$Q$59,"") -> 32173.08 | AK34: =IFERROR(P34/$P$58*$P$60,"") -> 0 | AL34: =IFERROR(AI34+AK34,"") -> 59700 | AM34: =IFERROR(AL34-AN34,"") -> 59700 | AN34: =IF(D34="India",AL34,0) -> 0 | AO34: =AJ34 -> 32173.08 | AP34: =IFERROR(AO34-AQ34,"") -> 32173.08 | AQ34: =IF(D34="India",AO34,0) -> 0
B35: Offshore | C35: {=IFERROR(_xlfn.IFS(B35="Onshore",$G$16,B35="Offshore","India"),"")} -> India | D35: India | E35: MS - Engineer | J35: =ROUND($G$21*$G$22*X35,0) -> 360 | L35: =IFERROR(INDEX(Bill_Rates!$L:$L,MATCH('MS Pricing'!$AD35,Bill_Rates!$J:$J,0)),"") -> 65 | M35: =$G$23-L35 -> 134 | N35: =IFERROR(L35+M35,"") -> 199 | O35: =IFERROR(INDEX(Bill_Rates!$O:$O,MATCH($AE35,Bill_Rates!$J:$J,0)),"") -> 19.93979 | P35: =IFERROR(N35*J35,"") -> 71640 | Q35: =IFERROR((J35+K35)*O35,"") -> 7178.3244 | R35: =IFERROR(P35-Q35,"") -> 64461.676 | S35: =IFERROR(R35/P35,"") -> 0.89980005 | T35: Managed Services | X35: {=INDEX('MS Lookups'!B1:E20,4,'MS Pricing'!AA20)} -> 0.3 | AB35: =IF(OR(G35="Change Management",G35="Enablement",G35="Strategy"),G35,"") | AC35: =E35 -> MS - Engineer | AD35: =G$16&C35&AA35&F35&AB35&H35&E35 -> UKIndiaMS - Engineer | AE35: =G$16&D35&H35&E35 -> UKIndiaMS - Engineer | AF35: =IFERROR(L35*J35,"") -> 23400 | AG35: =IFERROR(AF35-AH35,"") -> 0 | AH35: =IF(D35="India",AF35,0) -> 23400 | AI35: =IFERROR(P35+P35/$P$58*$P$59,"") -> 71640 | AJ35: =IFERROR(Q35+Q35/$Q$58*$Q$59,"") -> 7178.3244 | AK35: =IFERROR(P35/$P$58*$P$60,"") -> 0 | AL35: =IFERROR(AI35+AK35,"") -> 71640 | AM35: =IFERROR(AL35-AN35,"") -> 0 | AN35: =IF(D35="India",AL35,0) -> 71640 | AO35: =AJ35 -> 7178.3244 | AP35: =IFERROR(AO35-AQ35,"") -> 0 | AQ35: =IF(D35="India",AO35,0) -> 7178.3244
C36: {=IFERROR(_xlfn.IFS(B36="Onshore",$G$16,B36="Offshore","India"),"")} | J36: =ROUND($G$21*$G$22*X36,0) -> 0 | L36: =IFERROR(INDEX(Bill_Rates!$L:$L,MATCH('MS Pricing'!$AD36,Bill_Rates!$J:$J,0)),"") | N36: =IFERROR(L36+M36,"") | O36: =IFERROR(INDEX(Bill_Rates!$O:$O,MATCH($AE36,Bill_Rates!$J:$J,0)),"") | P36: =IFERROR(N36*J36,"") | Q36: =IFERROR((J36+K36)*O36,"") | R36: =IFERROR(P36-Q36,"") | S36: =IFERROR(R36/P36,"") | X36: {=INDEX('MS Lookups'!B1:E20,5,'MS Pricing'!AA20)} -> 0 | AB36: =IF(OR(G36="Change Management",G36="Enablement",G36="Strategy"),G36,"") | AC36: =E36 -> 0 | AD36: =G$16&C36&AA36&F36&AB36&H36&E36 -> UK | AE36: =G$16&D36&H36&E36 -> UK | AF36: =IFERROR(L36*J36,"") | AG36: =IFERROR(AF36-AH36,"") | AH36: =IF(D36="India",AF36,0) -> 0 | AI36: =IFERROR(P36+P36/$P$58*$P$59,"") | AJ36: =IFERROR(Q36+Q36/$Q$58*$Q$59,"") | AK36: =IFERROR(P36/$P$58*$P$60,"") | AL36: =IFERROR(AI36+AK36,"") | AM36: =IFERROR(AL36-AN36,"") | AN36: =IF(D36="India",AL36,0) -> 0 | AO36: =AJ36 | AP36: =IFERROR(AO36-AQ36,"") | AQ36: =IF(D36="India",AO36,0) -> 0
B37: Onshore | C37: {=IFERROR(_xlfn.IFS(B37="Onshore",$G$16,B37="Offshore","India"),"")} -> UK | D37: USA | E37: Project Manager | J37: =ROUND($G$21*$G$22*X37,0) -> 0 | L37: =IFERROR(INDEX(Bill_Rates!$L:$L,MATCH('MS Pricing'!$AD37,Bill_Rates!$J:$J,0)),"") -> 139 | M37: =$G$23-L37 -> 60 | N37: =IFERROR(L37+M37,"") -> 199 | O37: =IFERROR(INDEX(Bill_Rates!$O:$O,MATCH($AE37,Bill_Rates!$J:$J,0)),"") -> 96.2844 | P37: =IFERROR(N37*J37,"") -> 0 | Q37: =IFERROR((J37+K37)*O37,"") -> 0 | R37: =IFERROR(P37-Q37,"") -> 0 | S37: =IFERROR(R37/P37,"") | T37: Managed Services | X37: {=INDEX('MS Lookups'!B1:E20,6,'MS Pricing'!AA20)} -> 0 | AB37: =IF(OR(G37="Change Management",G37="Enablement",G37="Strategy"),G37,"") | AC37: =E37 -> Project Manager | AD37: =G$16&C37&AA37&F37&AB37&H37&E37 -> UKUKProject Manager | AE37: =G$16&D37&H37&E37 -> UKUSAProject Manager | AF37: =IFERROR(L37*J37,"") -> 0 | AG37: =IFERROR(AF37-AH37,"") -> 0 | AH37: =IF(D37="India",AF37,0) -> 0 | AI37: =IFERROR(P37+P37/$P$58*$P$59,"") -> 0 | AJ37: =IFERROR(Q37+Q37/$Q$58*$Q$59,"") -> 0 | AK37: =IFERROR(P37/$P$58*$P$60,"") -> 0 | AL37: =IFERROR(AI37+AK37,"") -> 0 | AM37: =IFERROR(AL37-AN37,"") -> 0 | AN37: =IF(D37="India",AL37,0) -> 0 | AO37: =AJ37 -> 0 | AP37: =IFERROR(AO37-AQ37,"") -> 0 | AQ37: =IF(D37="India",AO37,0) -> 0
B38: Onshore | C38: {=IFERROR(_xlfn.IFS(B38="Onshore",$G$16,B38="Offshore","India"),"")} -> UK | D38: USA | E38: Senior Project Manager or Program Manager | J38: =ROUND($G$21*$G$22*X38,0) -> 144 | L38: =IFERROR(INDEX(Bill_Rates!$L:$L,MATCH('MS Pricing'!$AD38,Bill_Rates!$J:$J,0)),"") -> 169 | M38: =$G$23-L38 -> 30 | N38: =IFERROR(L38+M38,"") -> 199 | O38: =IFERROR(INDEX(Bill_Rates!$O:$O,MATCH($AE38,Bill_Rates!$J:$J,0)),"") -> 119.7684 | P38: =IFERROR(N38*J38,"") -> 28656 | Q38: =IFERROR((J38+K38)*O38,"") -> 17246.65 | R38: =IFERROR(P38-Q38,"") -> 11409.35 | S38: =IFERROR(R38/P38,"") -> 0.39814874 | T38: Managed Services | X38: {=INDEX('MS Lookups'!B1:E20,7,'MS Pricing'!AA20)} -> 0.12 | AB38: =IF(OR(G38="Change Management",G38="Enablement",G38="Strategy"),G38,"") | AC38: =E38 -> Senior Project Manager or Program Manager | AD38: =G$16&C38&AA38&F38&AB38&H38&E38 -> UKUKSenior Project Manager or Program Manager | AE38: =G$16&D38&H38&E38 -> UKUSASenior Project Manager or Program Manager | AF38: =IFERROR(L38*J38,"") -> 24336 | AG38: =IFERROR(AF38-AH38,"") -> 24336 | AH38: =IF(D38="India",AF38,0) -> 0 | AI38: =IFERROR(P38+P38/$P$58*$P$59,"") -> 28656 | AJ38: =IFERROR(Q38+Q38/$Q$58*$Q$59,"") -> 17246.65 | AK38: =IFERROR(P38/$P$58*$P$60,"") -> 0 | AL38: =IFERROR(AI38+AK38,"") -> 28656 | AM38: =IFERROR(AL38-AN38,"") -> 28656 | AN38: =IF(D38="India",AL38,0) -> 0 | AO38: =AJ38 -> 17246.65 | AP38: =IFERROR(AO38-AQ38,"") -> 17246.65 | AQ38: =IF(D38="India",AO38,0) -> 0
C39: {=IFERROR(_xlfn.IFS(B39="Onshore",$G$16,B39="Offshore","India"),"")} | J39: =ROUND($G$21*$G$22*X39,0) -> 0 | L39: =IFERROR(INDEX(Bill_Rates!$L:$L,MATCH('MS Pricing'!$AD39,Bill_Rates!$J:$J,0)),"") | N39: =IFERROR(L39+M39,"") | O39: =IFERROR(INDEX(Bill_Rates!$O:$O,MATCH($AE39,Bill_Rates!$J:$J,0)),"") | P39: =IFERROR(N39*J39,"") | Q39: =IFERROR((J39+K39)*O39,"") | R39: =IFERROR(P39-Q39,"") | S39: =IFERROR(R39/P39,"") | X39: {=INDEX('MS Lookups'!B1:E20,8,'MS Pricing'!AA20)} -> 0 | AB39: =IF(OR(G39="Change Management",G39="Enablement",G39="Strategy"),G39,"") | AC39: =E39 -> 0 | AD39: =G$16&C39&AA39&F39&AB39&H39&E39 -> UK | AE39: =G$16&D39&H39&E39 -> UK | AF39: =IFERROR(L39*J39,"") | AG39: =IFERROR(AF39-AH39,"") | AH39: =IF(D39="India",AF39,0) -> 0 | AI39: =IFERROR(P39+P39/$P$58*$P$59,"") | AJ39: =IFERROR(Q39+Q39/$Q$58*$Q$59,"") | AK39: =IFERROR(P39/$P$58*$P$60,"") | AL39: =IFERROR(AI39+AK39,"") | AM39: =IFERROR(AL39-AN39,"") | AN39: =IF(D39="India",AL39,0) -> 0 | AO39: =AJ39 | AP39: =IFERROR(AO39-AQ39,"") | AQ39: =IF(D39="India",AO39,0) -> 0
B40: Offshore | C40: {=IFERROR(_xlfn.IFS(B40="Onshore",$G$16,B40="Offshore","India"),"")} -> India | D40: India | E40: MS - Platform Analyst | J40: =ROUND($G$21*$G$22*X40,0) -> 216 | L40: =IFERROR(INDEX(Bill_Rates!$L:$L,MATCH('MS Pricing'!$AD40,Bill_Rates!$J:$J,0)),"") -> 59 | M40: =$G$23-L40 -> 140 | N40: =IFERROR(L40+M40,"") -> 199 | O40: =IFERROR(INDEX(Bill_Rates!$O:$O,MATCH($AE40,Bill_Rates!$J:$J,0)),"") -> 11.16026 | P40: =IFERROR(N40*J40,"") -> 42984 | Q40: =IFERROR((J40+K40)*O40,"") -> 2410.6162 | R40: =IFERROR(P40-Q40,"") -> 40573.384 | S40: =IFERROR(R40/P40,"") -> 0.94391829 | T40: Managed Services | X40: {=INDEX('MS Lookups'!B1:E20,9,'MS Pricing'!AA20)} -> 0.18 | AB40: =IF(OR(G40="Change Management",G40="Enablement",G40="Strategy"),G40,"") | AC40: =E40 -> MS - Platform Analyst | AD40: =G$16&C40&AA40&F40&AB40&H40&E40 -> UKIndiaMS - Platform Analyst | AE40: =G$16&D40&H40&E40 -> UKIndiaMS - Platform Analyst | AF40: =IFERROR(L40*J40,"") -> 12744 | AG40: =IFERROR(AF40-AH40,"") -> 0 | AH40: =IF(D40="India",AF40,0) -> 12744 | AI40: =IFERROR(P40+P40/$P$58*$P$59,"") -> 42984 | AJ40: =IFERROR(Q40+Q40/$Q$58*$Q$59,"") -> 2410.6162 | AK40: =IFERROR(P40/$P$58*$P$60,"") -> 0 | AL40: =IFERROR(AI40+AK40,"") -> 42984 | AM40: =IFERROR(AL40-AN40,"") -> 0 | AN40: =IF(D40="India",AL40,0) -> 42984 | AO40: =AJ40 -> 2410.6162 | AP40: =IFERROR(AO40-AQ40,"") -> 0 | AQ40: =IF(D40="India",AO40,0) -> 2410.6162
C41: {=IFERROR(_xlfn.IFS(B41="Onshore",$G$16,B41="Offshore","India"),"")} | L41: =IFERROR(INDEX(Bill_Rates!$L:$L,MATCH('MS Pricing'!$AD41,Bill_Rates!$J:$J,0)),"") | N41: =IFERROR(L41+M41,"") | O41: =IFERROR(INDEX(Bill_Rates!$O:$O,MATCH($AE41,Bill_Rates!$J:$J,0)),"") | P41: =IFERROR(N41*J41,"") | Q41: =IFERROR((J41+K41)*O41,"") | R41: =IFERROR(P41-Q41,"") | S41: =IFERROR(R41/P41,"") | AB41: =IF(OR(G41="Change Management",G41="Enablement",G41="Strategy"),G41,"") | AC41: =E41 -> 0 | AD41: =G$16&C41&AA41&F41&AB41&H41&E41 -> UK | AE41: =G$16&D41&H41&E41 -> UK | AF41: =IFERROR(L41*J41,"") | AG41: =IFERROR(AF41-AH41,"") | AH41: =IF(D41="India",AF41,0) -> 0 | AI41: =IFERROR(P41+P41/$P$58*$P$59,"") | AJ41: =IFERROR(Q41+Q41/$Q$58*$Q$59,"") | AK41: =IFERROR(P41/$P$58*$P$60,"") | AL41: =IFERROR(AI41+AK41,"") | AM41: =IFERROR(AL41-AN41,"") | AN41: =IF(D41="India",AL41,0) -> 0 | AO41: =AJ41 | AP41: =IFERROR(AO41-AQ41,"") | AQ41: =IF(D41="India",AO41,0) -> 0
C42: {=IFERROR(_xlfn.IFS(B42="Onshore",$G$16,B42="Offshore","India"),"")} | L42: =IFERROR(INDEX(Bill_Rates!$L:$L,MATCH('MS Pricing'!$AD42,Bill_Rates!$J:$J,0)),"") | N42: =IFERROR(L42+M42,"") | O42: =IFERROR(INDEX(Bill_Rates!$O:$O,MATCH($AE42,Bill_Rates!$J:$J,0)),"") | P42: =IFERROR(N42*J42,"") | Q42: =IFERROR((J42+K42)*O42,"") | R42: =IFERROR(P42-Q42,"") | S42: =IFERROR(R42/P42,"") | AB42: =IF(OR(G42="Change Management",G42="Enablement",G42="Strategy"),G42,"") | AC42: =E42 -> 0 | AD42: =G$16&C42&AA42&F42&AB42&H42&E42 -> UK | AE42: =G$16&D42&H42&E42 -> UK | AF42: =IFERROR(L42*J42,"") | AG42: =IFERROR(AF42-AH42,"") | AH42: =IF(D42="India",AF42,0) -> 0 | AI42: =IFERROR(P42+P42/$P$58*$P$59,"") | AJ42: =IFERROR(Q42+Q42/$Q$58*$Q$59,"") | AK42: =IFERROR(P42/$P$58*$P$60,"") | AL42: =IFERROR(AI42+AK42,"") | AM42: =IFERROR(AL42-AN42,"") | AN42: =IF(D42="India",AL42,0) -> 0 | AO42: =AJ42 | AP42: =IFERROR(AO42-AQ42,"") | AQ42: =IF(D42="India",AO42,0) -> 0
C43: {=IFERROR(_xlfn.IFS(B43="Onshore",$G$16,B43="Offshore","India"),"")} | L43: =IFERROR(INDEX(Bill_Rates!$L:$L,MATCH('MS Pricing'!$AD43,Bill_Rates!$J:$J,0)),"") | N43: =IFERROR(L43+M43,"") | O43: =IFERROR(INDEX(Bill_Rates!$O:$O,MATCH($AE43,Bill_Rates!$J:$J,0)),"") | P43: =IFERROR(N43*J43,"") | Q43: =IFERROR((J43+K43)*O43,"") | R43: =IFERROR(P43-Q43,"") | S43: =IFERROR(R43/P43,"") | AB43: =IF(OR(G43="Change Management",G43="Enablement",G43="Strategy"),G43,"") | AC43: =E43 -> 0 | AD43: =G$16&C43&AA43&F43&AB43&H43&E43 -> UK | AE43: =G$16&D43&H43&E43 -> UK | AF43: =IFERROR(L43*J43,"") | AG43: =IFERROR(AF43-AH43,"") | AH43: =IF(D43="India",AF43,0) -> 0 | AI43: =IFERROR(P43+P43/$P$58*$P$59,"") | AJ43: =IFERROR(Q43+Q43/$Q$58*$Q$59,"") | AK43: =IFERROR(P43/$P$58*$P$60,"") | AL43: =IFERROR(AI43+AK43,"") | AM43: =IFERROR(AL43-AN43,"") | AN43: =IF(D43="India",AL43,0) -> 0 | AO43: =AJ43 | AP43: =IFERROR(AO43-AQ43,"") | AQ43: =IF(D43="India",AO43,0) -> 0
